<?xml version="1.0"?>
<robot name="planar2">
  
  <material name="red">
    <color rgba="1 0 0 0.8" />
  </material>
  <material name="green">
    <color rgba="0 1 0 0.8" />
  </material>

  <link name="base_link" />
  <link name="link1">
    <visual>
      <geometry>
        <box size="1 0.1 0.1" />
      </geometry>
      <origin xyz="0.5 0 0" />
      <material name="red" />
    </visual>
  </link>
  <link name="link2A">
    <visual>
      <geometry>
        <box size="1 0.1 0.1" />
      </geometry>
      <origin xyz="0.5 0 0" />
      <material name="green" />
    </visual>
  </link>
  <link name="endA">
    <visual>
      <geometry>
        <cylinder radius = "0.05" length="0.2" />
      </geometry>
    </visual>
  </link>
  <link name="link2B">
    <visual>
      <geometry>
        <box size="1 0.1 0.1" />
      </geometry>
      <origin xyz="0.5 0 0" />
      <material name="green" />
    </visual>
  </link>
  <link name="endB">
    <visual>
      <geometry>
        <cylinder radius = "0.05" length="0.2" />
      </geometry>
    </visual>
  </link>


  <joint name="q1" type="continuous">
    <parent link="base_link" />
    <child link="link1" />
    <axis xyz="0 0 1" />
  </joint>
  
  <joint name="q2A" type="continuous">
    <parent link="link1" />
    <child link="link2A" />
    <origin xyz="1 0 0" />
    <axis xyz="0 0 1" />
  </joint>
  
  <joint name="notajointA" type="fixed">
    <parent link="link2A" />
    <child link="endA" />
    <origin xyz="1 0 0" />
  </joint>
  <joint name="q2B" type="continuous">
    <parent link="link1" />
    <child link="link2B" />
    <origin xyz="1 0 0" />
    <axis xyz="0 0 1" />
  </joint>
  
  <joint name="notajointB" type="fixed">
    <parent link="link2B" />
    <child link="endB" />
    <origin xyz="1 0 0" />
  </joint>
  
</robot>
